Workbook
Name ASTER: #REF!
Name Dia: #REF!
Name fg: #REF!
Name Productos: [1]Dosis!$A$1:$C$65536
Name S: #REF!
Name SELEECION: #REF!

Sheet PGR Drench 2045 Frio 14-42
B1: 1 | C1: =B1+1 -> 2 | D1: =C1+1 -> 3 | E1: =D1+1 -> 4 | F1: =E1+1 -> 5 | I1: =F1+1 -> 6 | J1: =I1+1 -> 7 | M1: =J1+1 -> 8 | N1: =M1+1 -> 9 | Q1: =N1+1 -> 10 | R1: =Q1+1 -> 11 | U1: =R1+1 -> 12 | V1: =U1+1 -> 13 | Y1: =V1+1 -> 14 | Z1: =Y1+1 -> 15 | AA1: =#REF!+1 -> #REF!
B3: PROGRAMACION PARA DRENCH
A4: REVISADO 03/06/2020 | B4: SIEMBRAS MONTEALBO | I4: FURADAN 4F 48% LÍQUIDO
A5: SEM FENOLOGICA | B5: DRENCH BIOESTIMULANTE | C5: METODO DE APLICACIÓN 1 | D5: LITROS 1 CAMA | E5: PRODUCTO 1 | F5: CANTIDAD PRODCUTO 1 | G5: METODO DE APLICACIÓN 2 | H5: LITROS 2 CAMA | I5: PRODUCTO 2 | J5: CANTIDAD PRODCUTO 2 | K5: METODO DE APLICACIÓN 3 | L5: LITROS 3 CAMA | M5: PRODUCTO 3 | N5: CANTIDAD 6CC POR LITRO | O5: METODO DE APLICACIÓN 4 | P5: LITROS 4 CAMA | Q5: PRODUCTO 4 | R5: CANTIDAD 8CC POR LITRO | S5: METODO DE APLICACIÓN 5 | T5: LITROS 5 CAMA | U5: PRODUCTO 5 | V5: CANTIDAD EN FUNDAS | W5: METODO DE APLICACIÓN 6 | X5: LITROS 6 CAMA | Y5: PRODUCTO 6 | Z5: CANTIDAD PRODCUTO 6 | AA5: AA
A6: 1 | B6: 1 S AND | C6: Fumigacion | D6: 4 | E6: Bioenergia | F6: 1 | G6: Fumigacion | H6: 4 | K6: Fumigacion | L6: 4 | O6: Fumigacion | P6: 4 | S6: Fumigacion | T6: 4 | W6: Fumigacion | X6: 4
A7: 2 | B7: 2 S AND | C7: BOMBA | D7: 50 | E7: RAIZA | F7: 0.33 | G7: BOMBA | H7: 50 | I7: Humistar WG | J7: 0.2 | K7: BOMBA | L7: 50 | M7: Beauveria | N7: 6 | O7: BOMBA | P7: 50 | Q7: Paecilomyces | R7: 8 | S7: BOMBA | T7: 50 | U7: Trichoderma | V7: 1 | W7: BOMBA | X7: 50
A8: 3 | B8: 3 S AND | C8: BOMBA | D8: 50 | E8: Nitrato calcio | F8: 2 | G8: BOMBA | H8: 50 | K8: BOMBA | L8: 50 | M8: Beauveria | N8: 6 | O8: BOMBA | P8: 50 | Q8: Paecilomyces | R8: 8 | S8: BOMBA | T8: 50 | W8: BOMBA | X8: 50
A9: 4 | B9: 4 S AND | C9: BOMBA | D9: 50 | E9: RAIZA | F9: 0.33 | G9: BOMBA | H9: 50 | I9: Humistar WG | J9: 0.2 | K9: BOMBA | L9: 50 | M9: Beauveria | N9: 6 | O9: BOMBA | P9: 50 | Q9: Paecilomyces | R9: 8 | S9: BOMBA | T9: 50 | U9: Trichoderma | V9: 1 | W9: BOMBA | X9: 50
A10: 5 | B10: 5 S AND | C10: BOMBA | D10: 50 | E10: OZONIC | F10: 0.88 | G10: BOMBA | H10: 50 | K10: BOMBA | L10: 50 | O10: BOMBA | P10: 50 | S10: BOMBA | T10: 50 | W10: BOMBA | X10: 50 | AB10: En foliar 2 cc / litro, No repetir la fumigación el mismo día
A11: 6 | B11: 6 S AND | C11: BOMBA | D11: 50 | E11: Nitrato calcio | F11: 2 | G11: BOMBA | H11: 50 | K11: BOMBA | L11: 50 | M11: Beauveria | N11: 6 | O11: BOMBA | P11: 50 | Q11: Paecilomyces | R11: 8 | S11: BOMBA | T11: 50 | W11: BOMBA | X11: 50
A12: 7 | B12: 7 S AND | C12: BOMBA | D12: 50 | E12: Novak | F12: 0.48 | G12: BOMBA | H12: 50 | I12: NAKAR 20 EC | J12: =25/50 -> 0.5 | K12: BOMBA | L12: 50 | O12: BOMBA | P12: 50 | S12: BOMBA | T12: 50 | W12: BOMBA | X12: 50 | AB12: En foliar 0,8 cc / litro, No repetir la fumigación el mismo día
A13: 8 | B13: 8 S AND | C13: BOMBA | D13: 50 | E13: ALCAPLANT | F13: 1.1 | G13: BOMBA | H13: 50 | K13: BOMBA | L13: 50 | O13: BOMBA | P13: 50 | S13: BOMBA | T13: 50 | W13: BOMBA | X13: 50
A14: 9 | B14: 9 S AND | C14: BOMBA | D14: 50 | E14: RAIZA | F14: 0.33 | G14: BOMBA | H14: 50 | K14: BOMBA | L14: 50 | M14: Beauveria | N14: 6 | O14: BOMBA | P14: 50 | Q14: Paecilomyces | R14: 8 | S14: BOMBA | T14: 50 | W14: BOMBA | X14: 50
A15: 10 | B15: 10 S AND | C15: BOMBA | D15: 50 | E15: ALCAPLANT | F15: 1.1 | G15: BOMBA | H15: 50 | K15: BOMBA | L15: 50 | O15: BOMBA | P15: 50 | S15: BOMBA | T15: 50 | W15: BOMBA | X15: 50
A16: 11 | B16: 11 S AND | C16: BOMBA | G16: BOMBA | K16: BOMBA | O16: BOMBA | S16: BOMBA | W16: BOMBA
A17: 12 | B17: 12 S AND | C17: BOMBA | D17: 50 | E17: ALCAPLANT | F17: 1.1 | G17: BOMBA | H17: 50 | K17: BOMBA | L17: 50 | O17: BOMBA | P17: 50 | S17: BOMBA | T17: 50 | W17: BOMBA | X17: 50
A18: 13 | B18: 13 S AND | C18: BOMBA | D18: 50 | E18: Muriato de k blanco | F18: 1.45 | G18: BOMBA | H18: 50 | K18: BOMBA | L18: 50 | O18: BOMBA | P18: 50 | S18: BOMBA | T18: 50 | W18: BOMBA | X18: 50
A19: 14 | B19: 14 S AND | C19: BOMBA | G19: BOMBA | K19: BOMBA | O19: BOMBA | S19: BOMBA | W19: BOMBA
A20: 15 | B20: 15 S AND | C20: BOMBA | D20: 50 | E20: ALCAPLANT | F20: 1.1 | G20: BOMBA | H20: 50 | K20: BOMBA | L20: 50 | O20: BOMBA | P20: 50 | S20: BOMBA | T20: 50 | W20: BOMBA | X20: 50
A21: 16 | B21: 16 S AND | C21: Fumigacion | D21: 7 | E21: Vitavax flo | F21: 2 | G21: Fumigacion | H21: 7 | I21: Agral | J21: 0.2 | K21: Fumigacion | L21: 7 | O21: Fumigacion | P21: 7 | S21: Fumigacion | T21: 7 | W21: Fumigacion | X21: 7
A22: 17 | B22: 17 S AND
A23: 18 | B23: 18 S AND | C23: BOMBA | D23: 50 | E23: ALBA PAC | F23: 15 | G23: BOMBA | H23: 50 | K23: BOMBA | L23: 50 | O23: BOMBA | P23: 50 | S23: BOMBA | T23: 50 | W23: BOMBA | X23: 50 | AB23: 2 semanas antes de fin de cosecha. Reducir 750 gr de la aplicación de cal en la poda
A24: 19 | B24: 19 S AND
A25: 20 | B25: 20 S AND
B26: SIEMBRAS CLOUD
A27: SEM FENOLOGICA | B27: DRENCH BIOESTIMULANTE | C27: METODO DE APLICACIÓN 1 | D27: LITROS 1 CAMA | E27: PRODUCTO 1 | F27: CANTIDAD PRODCUTO 1 | G27: METODO DE APLICACIÓN 2 | H27: LITROS 2 CAMA | I27: PRODUCTO 2 | J27: CANTIDAD PRODCUTO 2 | K27: METODO DE APLICACIÓN 3 | L27: LITROS 3 CAMA | M27: PRODUCTO 3 | N27: CANTIDAD 6CC POR LITRO | O27: METODO DE APLICACIÓN 4 | P27: LITROS 4 CAMA | Q27: PRODUCTO 4 | R27: CANTIDAD 8CC POR LITRO | S27: METODO DE APLICACIÓN 5 | T27: LITROS 5 CAMA | U27: PRODUCTO 5 | V27: CANTIDAD EN FUNDAS | W27: METODO DE APLICACIÓN 6 | X27: LITROS 6 CAMA | Y27: PRODUCTO 6 | Z27: CANTIDAD PRODCUTO 6 | AA27: AA
A28: 1 | B28: 1 S CLO | C28: Fumigacion | D28: 4 | E28: Bioenergia | F28: 1 | G28: Fumigacion | H28: 4 | K28: Fumigacion | L28: 4 | O28: Fumigacion | P28: 4 | S28: Fumigacion | T28: 4 | W28: Fumigacion | X28: 4
A29: 2 | B29: 2 S CLO | C29: BOMBA | D29: 50 | E29: RAIZA | F29: 0.33 | G29: BOMBA | H29: 50 | I29: Humistar WG | J29: 0.2 | K29: BOMBA | L29: 50 | M29: Beauveria | N29: 6 | O29: BOMBA | P29: 50 | Q29: Paecilomyces | R29: 8 | S29: BOMBA | T29: 50 | U29: Trichoderma | V29: 1 | W29: BOMBA | X29: 50
A30: 3 | B30: 3 S CLO | C30: BOMBA | D30: 50 | E30: Nitrato calcio | F30: 2 | G30: BOMBA | H30: 50 | K30: BOMBA | L30: 50 | M30: Beauveria | N30: 6 | O30: BOMBA | P30: 50 | Q30: Paecilomyces | R30: 8 | S30: BOMBA | T30: 50 | W30: BOMBA | X30: 50
A31: 4 | B31: 4 S CLO | C31: BOMBA | D31: 50 | E31: RAIZA | F31: 0.33 | G31: BOMBA | H31: 50 | I31: Humistar WG | J31: 0.2 | K31: BOMBA | L31: 50 | M31: Beauveria | N31: 6 | O31: BOMBA | P31: 50 | Q31: Paecilomyces | R31: 8 | S31: BOMBA | T31: 50 | U31: Trichoderma | V31: 1 | W31: BOMBA | X31: 50
A32: 5 | B32: 5 S CLO | C32: BOMBA | D32: 50 | E32: OZONIC | F32: 0.88 | G32: BOMBA | H32: 50 | K32: BOMBA | L32: 50 | O32: BOMBA | P32: 50 | S32: BOMBA | T32: 50 | W32: BOMBA | X32: 50 | AB32: En foliar 2 cc / litro, No repetir la fumigación el mismo día
A33: 6 | B33: 6 S CLO | C33: BOMBA | D33: 50 | E33: Nitrato calcio | F33: 2 | G33: BOMBA | H33: 50 | K33: BOMBA | L33: 50 | M33: Beauveria | N33: 6 | O33: BOMBA | P33: 50 | Q33: Paecilomyces | R33: 8 | S33: BOMBA | T33: 50 | W33: BOMBA | X33: 50
A34: 7 | B34: 7 S CLO | C34: BOMBA | D34: 50 | E34: Novak | F34: 0.48 | G34: BOMBA | H34: 50 | I34: NAKAR 20 EC | J34: =25/50 -> 0.5 | K34: BOMBA | L34: 50 | O34: BOMBA | P34: 50 | S34: BOMBA | T34: 50 | W34: BOMBA | X34: 50 | AB34: En foliar 0,8 cc / litro, No repetir la fumigación el mismo día
A35: 8 | B35: 8 S CLO | C35: BOMBA | D35: 50 | E35: ALCAPLANT | F35: 1.1 | G35: BOMBA | H35: 50 | K35: BOMBA | L35: 50 | O35: BOMBA | P35: 50 | S35: BOMBA | T35: 50 | W35: BOMBA | X35: 50
A36: 9 | B36: 9 S CLO | C36: BOMBA | D36: 50 | E36: RAIZA | F36: 0.33 | G36: BOMBA | H36: 50 | K36: BOMBA | L36: 50 | M36: Beauveria | N36: 6 | O36: BOMBA | P36: 50 | Q36: Paecilomyces | R36: 8 | S36: BOMBA | T36: 50 | W36: BOMBA | X36: 50
A37: 10 | B37: 10 S CLO | C37: BOMBA | D37: 50 | E37: ALCAPLANT | F37: 1.1 | G37: BOMBA | H37: 50 | K37: BOMBA | L37: 50 | O37: BOMBA | P37: 50 | S37: BOMBA | T37: 50 | W37: BOMBA | X37: 50
A38: 11 | B38: 11 S CLO | C38: BOMBA | G38: BOMBA | K38: BOMBA | O38: BOMBA | S38: BOMBA | W38: BOMBA
A39: 12 | B39: 12 S CLO | C39: BOMBA | D39: 50 | E39: ALCAPLANT | F39: 1.1 | G39: BOMBA | H39: 50 | K39: BOMBA | L39: 50 | O39: BOMBA | P39: 50 | S39: BOMBA | T39: 50 | W39: BOMBA | X39: 50
A40: 13 | B40: 13 S CLO | C40: BOMBA | D40: 50 | E40: Muriato de k blanco | F40: 1.45 | G40: BOMBA | H40: 50 | K40: BOMBA | L40: 50 | O40: BOMBA | P40: 50 | S40: BOMBA | T40: 50 | W40: BOMBA | X40: 50
A41: 14 | B41: 14 S CLO | C41: BOMBA | G41: BOMBA | K41: BOMBA | O41: BOMBA | S41: BOMBA | W41: BOMBA
...

Sheet 1643 Cal y Alcaplant
A1: Aplicaciones de Cal y Alcaplant en Gypsophilas
A2: Fecha: 24 / Oct / 2016
A4: Aplicación | B4: Producto | C4: Dosis (cc o gr / litro) | D4: Semana Poda | E4: Semana Siembra
A5: 1 | B5: Hidróxido de Calcio (Cal) | C5: 30 | D5: 3 | E5: 4
A6: 2 | B6: Hidróxido de Calcio (Cal) | C6: 15 | D6: 6 | E6: 7
A7: 3 | B7: Alcaplant | C7: 4 | D7: 8 | E7: 9
A8: 4 | B8: Alcaplant | C8: 4 | D8: 10 | E8: 11
A9: 5 | B9: Alcaplant | C9: 6 | D9: 3 semanas antes de la poda
A11: No aplicar estos productos el mismo día que se apliquen pesticidas

Sheet Fusarium Nematodos 2008
A1: Plan de acción problemas sanitarios semana 2008
A2: Fecha: 18-febrero-2020
A4: NEMÁTODOS
A6: Análisis de Guipi, compost malima; ecogreen, peatmoos (2 marcas); cascajo;
A7: Repetir análisis en todos los bloques
A9: Resultado de Análisis
A10: Bq | B10: Nemalam - Meloidogyne por 100 g de suelo | C10: Hilsea - Meloidogyne por 100 g de suelo | D10: Hilsea - Paratilenchus por 100 g de suelo
A11: 104 | B11: 250
A12: 105 | B12: 750
A13: 107 | B13: 2500
A14: 108 | B14: 1500
A15: 108 | C15: 600 | D15: 300
A16: 305 | B16: 250
A17: 337 | B17: 750
A18: En general, el umbral económico esta en 100 - 200 individuos por 100 g de suelo
A20: Informacion General de Nemátodos
A21: Las enfermedades causadas por nematodos se manifiestan con síntomas en las raices como agallas, lesiones
A22: necróticas, proliferación de raíces secundarias y pobre crecimiento radicular, lo que se traduce en clorosis y en
A23: general plantas débiles con pobre crecimiento.
A25: Los síntomas causados por los nematodos que atacan partas aéreas, son manchas foliares, putrefacciones y
A26: distorsiones en cuello y bulbos, así como agallas en las flores. Necrosis del xilema y marchitez
A28: Siembras y Podas:
B29: Producto | C29: Dosis normal g / m2 | D29: Dosis bloques problema
A30: Siembra: | B30: Agrocelhone FE (DICLOROPROPENO 38% y CLOROPRICRINA 57%) | C30: 50 | D30: 60
B31: Agrocelhone NE (DICLOROPROPENO 80,3% y CLOROPRICRINA 44%) | C31: 50 | D31: 60
A32: Poda: | B32: Rugby | C32: 5 g / m2 | D32: 7,5 g / m2
A33: Sem 7: | B33: Nakar | C33: 25 cc / cama
A36: Manejo de Nemátodos:
A37: Evitar la contaminación entre bloques con desinfección de manos y botas con Neuthox a 60 cc/lit y herramientas
A38: con BAC a 5 cc / litro
A39: Incorporación al suelo de altas cantidades de materia orgánica: 18 sacos/cama en siembras normales
A40: 25 sacos/cama en el área nueva. Cada saco es de 6 paladas llenas.
A41: Niveles de cloro libre en gotero en agua de 2-4 ppm. Con neuthox en MH y pastillas de cloro en SJP
A42: Nivel adecuado de cal en el suelo. En gypso encalar si tenemos pH 7,2 o inferior
A43: Mantener el protocolo para bacterias, pues en ambos casos debemos reducir contagios
A44: Dos pases de arado, con 15 días de separación antes de la desinfección
A45: Escarificados en todos los bloques antes del GA3 y en los filos de la cama 2 semanas antes de cosecha
A46: Desinfectar los escarificadores a cada cambio de camas
A47: Manejo Biológico: Peacelocyses
A49: Producto | B49: Trichoderma | D49: Beauveria | F49: Paecylomices
...

Sheet Programa Drench
B1: 1 | C1: =B1+1 -> 2 | D1: =C1+1 -> 3 | E1: =D1+1 -> 4 | F1: =E1+1 -> 5 | I1: =F1+1 -> 6 | J1: =I1+1 -> 7 | M1: =J1+1 -> 8 | N1: =M1+1 -> 9 | Q1: =N1+1 -> 10 | R1: =Q1+1 -> 11 | U1: =R1+1 -> 12 | V1: =U1+1 -> 13 | Y1: =V1+1 -> 14 | Z1: =Y1+1 -> 15 | AA1: =#REF!+1 -> #REF!
A2: Frio_Caliente
B3: PROGRAMACION PARA DRENCH
B4: SIEMBRAS MONTEALBO | I4: FURADAN 4F 48% LÍQUIDO
A5: SEM FENOLOGICA | B5: DRENCH BIOESTIMULANTE | C5: METODO DE APLICACIÓN 1 | D5: LITROS 1 CAMA | E5: PRODUCTO 1 | F5: CANTIDAD PRODCUTO 1 | G5: METODO DE APLICACIÓN 2 | H5: LITROS 2 CAMA | I5: PRODUCTO 2 | J5: CANTIDAD PRODCUTO 2 | K5: METODO DE APLICACIÓN 3 | L5: LITROS 3 CAMA | M5: PRODUCTO 3 | N5: CANTIDAD 6CC POR LITRO | O5: METODO DE APLICACIÓN 4 | P5: LITROS 4 CAMA | Q5: PRODUCTO 4 | R5: CANTIDAD 8CC POR LITRO | S5: METODO DE APLICACIÓN 5 | T5: LITROS 5 CAMA | U5: PRODUCTO 5 | V5: CANTIDAD EN FUNDAS | W5: METODO DE APLICACIÓN 6 | X5: LITROS 6 CAMA | Y5: PRODUCTO 6 | Z5: CANTIDAD PRODCUTO 6 | AA5: AA
A6: 1 | B6: 1 S AND | C6: Fumigacion | D6: 4 | E6: Bioenergia | F6: 1 | G6: Fumigacion | H6: 4 | K6: Fumigacion | L6: 4 | O6: Fumigacion | P6: 4 | S6: Fumigacion | T6: 4 | W6: Fumigacion | X6: 4 | AA6: =F6+J6+N6+R6+V6+Z6 -> 1
A7: 2 | B7: 2 S AND | C7: BOMBA | D7: 50 | E7: RAIZA | F7: 0.33 | G7: BOMBA | H7: 50 | I7: Humistar WG | J7: 0.2 | K7: BOMBA | L7: 50 | M7: Beauveria | N7: 6 | O7: BOMBA | P7: 50 | Q7: Paecilomyces | R7: 8 | S7: BOMBA | T7: 50 | U7: Trichoderma | V7: 1 | W7: BOMBA | X7: 50 | AA7: =F7+J7+N7+R7+V7+Z7 -> 15.53
A8: 3 | B8: 3 S AND | C8: BOMBA | D8: 50 | E8: Nitrato calcio | F8: 2 | G8: BOMBA | H8: 50 | K8: BOMBA | L8: 50 | M8: Beauveria | N8: 6 | O8: BOMBA | P8: 50 | Q8: Paecilomyces | R8: 8 | S8: BOMBA | T8: 50 | W8: BOMBA | X8: 50 | AA8: =F8+J8+N8+R8+V8+Z8 -> 16
A9: 4 | B9: 4 S AND | C9: BOMBA | D9: 50 | E9: RAIZA | F9: 0.33 | G9: BOMBA | H9: 50 | I9: Humistar WG | J9: 0.2 | K9: BOMBA | L9: 50 | M9: Beauveria | N9: 6 | O9: BOMBA | P9: 50 | Q9: Paecilomyces | R9: 8 | S9: BOMBA | T9: 50 | U9: Trichoderma | V9: 1 | W9: BOMBA | X9: 50 | AA9: =F9+J9+N9+R9+V9+Z9 -> 15.53
A10: 5 | B10: 5 S AND | C10: BOMBA | D10: 50 | E10: OZONIC | F10: 0.88 | G10: BOMBA | H10: 50 | K10: BOMBA | L10: 50 | O10: BOMBA | P10: 50 | S10: BOMBA | T10: 50 | W10: BOMBA | X10: 50 | AA10: =F10+J10+N10+R10+V10+Z10 -> 0.88 | AB10: En foliar 2 cc / litro, No repetir la fumigación el mismo día
A11: 6 | B11: 6 S AND | C11: BOMBA | D11: 50 | E11: Nitrato calcio | F11: 2 | G11: BOMBA | H11: 50 | K11: BOMBA | L11: 50 | M11: Beauveria | N11: 6 | O11: BOMBA | P11: 50 | Q11: Paecilomyces | R11: 8 | S11: BOMBA | T11: 50 | W11: BOMBA | X11: 50 | AA11: =F11+J11+N11+R11+V11+Z11 -> 16
A12: 7 | B12: 7 S AND | C12: BOMBA | D12: 50 | E12: Novak | F12: 0.48 | G12: BOMBA | H12: 50 | I12: NAKAR 20 EC | J12: =25/50 -> 0.5 | K12: BOMBA | L12: 50 | O12: BOMBA | P12: 50 | S12: BOMBA | T12: 50 | W12: BOMBA | X12: 50 | AA12: =F12+J12+N12+R12+V12+Z12 -> 0.98 | AB12: En foliar 0,8 cc / litro, No repetir la fumigación el mismo día
A13: 8 | B13: 8 S AND | C13: BOMBA | D13: 50 | E13: ALCAPLANT | F13: 1.1 | G13: BOMBA | H13: 50 | K13: BOMBA | L13: 50 | O13: BOMBA | P13: 50 | S13: BOMBA | T13: 50 | W13: BOMBA | X13: 50 | AA13: =F13+J13+N13+R13+V13+Z13 -> 1.1
A14: 9 | B14: 9 S AND | C14: BOMBA | D14: 50 | E14: RAIZA | F14: 0.33 | G14: BOMBA | H14: 50 | K14: BOMBA | L14: 50 | M14: Beauveria | N14: 6 | O14: BOMBA | P14: 50 | Q14: Paecilomyces | R14: 8 | S14: BOMBA | T14: 50 | W14: BOMBA | X14: 50 | AA14: =F14+J14+N14+R14+V14+Z14 -> 14.33
A15: 10 | B15: 10 S AND | C15: BOMBA | D15: 50 | E15: ALCAPLANT | F15: 1.1 | G15: BOMBA | H15: 50 | K15: BOMBA | L15: 50 | O15: BOMBA | P15: 50 | S15: BOMBA | T15: 50 | W15: BOMBA | X15: 50 | AA15: =F15+J15+N15+R15+V15+Z15 -> 1.1
A16: 11 | B16: 11 S AND | C16: BOMBA | G16: BOMBA | K16: BOMBA | O16: BOMBA | S16: BOMBA | W16: BOMBA | AA16: =F16+J16+N16+R16+V16+Z16 -> 0
A17: 12 | B17: 12 S AND | C17: BOMBA | D17: 50 | E17: ALCAPLANT | F17: 1.1 | G17: BOMBA | H17: 50 | K17: BOMBA | L17: 50 | O17: BOMBA | P17: 50 | S17: BOMBA | T17: 50 | W17: BOMBA | X17: 50 | AA17: =F17+J17+N17+R17+V17+Z17 -> 1.1
A18: 13 | B18: 13 S AND | C18: BOMBA | D18: 50 | E18: Muriato de k blanco | F18: 1.45 | G18: BOMBA | H18: 50 | K18: BOMBA | L18: 50 | O18: BOMBA | P18: 50 | S18: BOMBA | T18: 50 | W18: BOMBA | X18: 50 | AA18: =F18+J18+N18+R18+V18+Z18 -> 1.45
A19: 14 | B19: 14 S AND | C19: BOMBA | G19: BOMBA | K19: BOMBA | O19: BOMBA | S19: BOMBA | W19: BOMBA | AA19: =F19+J19+N19+R19+V19+Z19 -> 0
A20: 15 | B20: 15 S AND | C20: BOMBA | D20: 50 | E20: ALCAPLANT | F20: 1.1 | G20: BOMBA | H20: 50 | K20: BOMBA | L20: 50 | O20: BOMBA | P20: 50 | S20: BOMBA | T20: 50 | W20: BOMBA | X20: 50 | AA20: =F20+J20+N20+R20+V20+Z20 -> 1.1
A21: 16 | B21: 16 S AND | C21: Fumigacion | D21: 7 | E21: Vitavax flo | F21: 2 | G21: Fumigacion | H21: 7 | I21: Agral | J21: 0.2 | K21: Fumigacion | L21: 7 | O21: Fumigacion | P21: 7 | S21: Fumigacion | T21: 7 | W21: Fumigacion | X21: 7 | AA21: =F21+J21+N21+R21+V21+Z21 -> 2.2
A22: 17 | B22: 17 S AND | AA22: =F22+J22+N22+R22+V22+Z22 -> 0
A23: 18 | B23: 18 S AND | C23: BOMBA | D23: 50 | E23: ALBA PAC | F23: 15 | G23: BOMBA | H23: 50 | K23: BOMBA | L23: 50 | O23: BOMBA | P23: 50 | S23: BOMBA | T23: 50 | W23: BOMBA | X23: 50 | AA23: =F23+J23+N23+R23+V23+Z23 -> 15 | AB23: 2 semanas antes de fin de cosecha. Reducir 750 gr de la aplicación de cal en la poda
A24: 19 | B24: 19 S AND | AA24: =F24+J24+N24+R24+V24+Z24 -> 0
A25: 20 | B25: 20 S AND | AA25: =F25+J25+N25+R25+V25+Z25 -> 0
B26: SIEMBRAS CLOUD
A27: SEM FENOLOGICA | B27: DRENCH BIOESTIMULANTE | C27: METODO DE APLICACIÓN 1 | D27: LITROS 1 CAMA | E27: PRODUCTO 1 | F27: CANTIDAD PRODCUTO 1 | G27: METODO DE APLICACIÓN 2 | H27: LITROS 2 CAMA | I27: PRODUCTO 2 | J27: CANTIDAD PRODCUTO 2 | K27: METODO DE APLICACIÓN 3 | L27: LITROS 3 CAMA | M27: PRODUCTO 3 | N27: CANTIDAD 6CC POR LITRO | O27: METODO DE APLICACIÓN 4 | P27: LITROS 4 CAMA | Q27: PRODUCTO 4 | R27: CANTIDAD 8CC POR LITRO | S27: METODO DE APLICACIÓN 5 | T27: LITROS 5 CAMA | U27: PRODUCTO 5 | V27: CANTIDAD EN FUNDAS | W27: METODO DE APLICACIÓN 6 | X27: LITROS 6 CAMA | Y27: PRODUCTO 6 | Z27: CANTIDAD PRODCUTO 6 | AA27: AA
A28: 1 | B28: 1 S CLO | C28: Fumigacion | D28: 4 | E28: Bioenergia | F28: 1 | G28: Fumigacion | H28: 4 | I28: Agral | J28: 0.2 | AA28: =F28+J28+N28+R28+V28+Z28 -> 1.2
A29: 2 | B29: 2 S CLO | C29: BOMBA | D29: 50 | E29: RAIZA | F29: 0.33 | G29: BOMBA | H29: 50 | I29: HUMISTAR WG | J29: 0.2 | K29: BOMBA | L29: 50 | M29: Serenade | N29: 0.18 | AA29: =F29+J29+N29+R29+V29+Z29 -> 0.71
A30: 3 | B30: 3 S CLO | C30: BOMBA | D30: 50 | E30: Alto 100 | F30: 0.64 | AA30: =F30+J30+N30+R30+V30+Z30 -> 0.64
A31: 4 | B31: 4 S CLO | C31: Fumigacion | D31: 7 | E31: FOLIOGOLD | F31: 2 | G31: Fumigacion | H31: 7 | I31: Agral | J31: 0.2 | AA31: =F31+J31+N31+R31+V31+Z31 -> 2.2
A32: 5 | B32: 5 S CLO | C32: BOMBA | D32: 50 | E32: RAIZA | F32: 0.33 | G32: BOMBA | H32: 50 | I32: HUMISTAR WG | J32: 0.2 | K32: BOMBA | L32: 50 | M32: Beauveria | N32: 6 | O32: BOMBA | P32: 50 | Q32: Paecilomyces | R32: 8 | S32: BOMBA | T32: 50 | U32: Trichoderma | V32: 1 | AA32: =F32+J32+N32+R32+V32+Z32 -> 15.53 | AB32: En foliar 2 cc / litro, No repetir la fumigación el mismo día
A33: 6 | B33: 6 S CLO | C33: Fumigacion | D33: 7 | E33: OZONIC | F33: 2 | G33: Fumigacion | H33: 7 | I33: Agral | J33: 0.2 | AA33: =F33+J33+N33+R33+V33+Z33 -> 2.2
A34: 7 | B34: 7 S CLO | C34: BOMBA | D34: 50 | E34: ALCAPLANT | F34: 1.1 | AA34: =F34+J34+N34+R34+V34+Z34 -> 1.1 | AB34: En foliar 0,8 cc / litro, No repetir la fumigación el mismo día
A35: 8 | B35: 8 S CLO | C35: BOMBA | D35: 50 | E35: NAKAR 20 EC | F35: 0.5 | G35: BOMBA | H35: 50 | I35: FUNGAFLOR | J35: 0.2 | AA35: =F35+J35+N35+R35+V35+Z35 -> 0.7
A36: 9 | B36: 9 S CLO | C36: BOMBA | D36: 50 | E36: RAIZA | F36: 0.33 | G36: BOMBA | H36: 50 | I36: HUMISTAR WG | J36: 0.2 | K36: BOMBA | L36: 50 | M36: Serenade | N36: 0.18 | AA36: =F36+J36+N36+R36+V36+Z36 -> 0.71
A37: 10 | B37: 10 S CLO | C37: BOMBA | D37: 50 | E37: Beauveria | F37: 6 | G37: BOMBA | H37: 50 | I37: Paecilomyces | J37: 8 | S37: BOMBA | T37: 50 | U37: Trichoderma | V37: 1 | AA37: =F37+J37+N37+R37+V37+Z37 -> 15
A38: 11 | B38: 11 S CLO | C38: Fumigacion | D38: 10 | E38: Bac | F38: 2 | G38: Fumigacion | H38: 10 | I38: Agral | J38: 0.2 | AA38: =F38+J38+N38+R38+V38+Z38 -> 2.2
A39: 12 | B39: 12 S CLO | C39: Boquilla B7 | D39: 7 | E39: Sulfex | F39: 1.5 | G39: Boquilla B7 | H39: 7 | I39: Agral | J39: 0.2 | AA39: =F39+J39+N39+R39+V39+Z39 -> 1.7
A40: 13 | B40: 13 S CLO | C40: BOMBA | D40: 50 | E40: ALCAPLANT | F40: 1.1 | AA40: =F40+J40+N40+R40+V40+Z40 -> 1.1
...

Sheet PROGRAMA DRENCH PASO 1
A1: =IF(($J$1-C1)<=52,($J$1-C1-100+52+1),($J$1-C1+1)) -> #VALUE! | B1: =IF(($J$1-D1)>=52,($J$1-D1-100+52+1),IF(($J$1-D1)<=48,($J$1-D1+100-52-1),($J$1-D1+1))) -> 2572 | C1: PROGRAMACION PARA DRENCH | I1: 46146 | J1: =MID(YEAR(I1),3,2)&IF(AND(WEEKNUM(I1,17)<=9,WEEKNUM(I1,17)>=1),"0"&(WEEKNUM(I1,17)),WEEKNUM(I1)) -> 2619 | M1: PESAR | Q1: PESAR | U1: PESAR | Y1: PESAR | AC1: PESAR | AG1: PESAR
A2: SEM FENOLOGICA | B2: BLOQUE | C2: SEM P/S | D2: AREA | E2: PODA SIEMBRA | F2: VARIEDAD | G2: P/S | H2: CATEGORIA FENOLOGICA | I2: # CAMAS 30M2 | J2: HRS | K2: LITROS 1 CAMA | L2: PRODUCTO 1 | M2: CANTIDAD PRODCUTO 1 | N2: LITROS BLOQUE | O2: LITROS 2 CAMA | P2: PRODUCTO 2 | Q2: CANTIDAD PRODCUTO 2 | R2: LITROS BLOQUE | S2: LITROS 3 CAMA | T2: PRODUCTO 3 | U2: CANTIDAD 6CC POR LITRO | V2: LITROS BLOQUE | W2: LITROS 4 CAMA | X2: PRODUCTO 4 | Y2: CANTIDAD 8CC POR LITRO | Z2: LITROS BLOQUE | AA2: LITROS 5 CAMA | AB2: PRODUCTO 5 | AC2: CANTIDAD EN FUNDAS | AD2: LITROS BLOQUE | AE2: LITROS 6 CAMA | AF2: PRODUCTO 6 | AG2: CANTIDAD PRODCUTO 6 | AH2: LITROS 6 CAMA | AI2: AA
A3: =IF(($J$1-C3)>=52,($J$1-C3-100+52+1),($J$1-C3+1)) -> 15 | B3: 27 | C3: 2605 | D3: CV | E3: P1 | F3: CLO | G3: =MID(E3,1,1) -> P | H3: =CONCATENATE(A3," ",G3," ",F3) -> 15 P CLO | I3: =IF(D3="MM1",VLOOKUP($B3,'Inf Bloques'!$A$1:$K$453,11,FALSE)*1,VLOOKUP($B3,'Inf Bloques'!$A$1:$K$453,11,FALSE)) -> 37.95155 | J3: =I3/9 -> 4.2168389 | K3: =IFERROR(ROUND(IF($D3="SSJ",(VLOOKUP($H3,'Programa Drench'!$B$6:$AA$182,MATCH(K$2,'Programa Drench'!$B$5:$AA$5,0),FALSE)),VLOOKUP($H3,'Programa Drench'!$B$6:$AA$182,MATCH(K$2,'Programa Drench'!$B$5:$AA$5,0),FALSE)),1),0) -> 7 | L3: =IFERROR((VLOOKUP($H3,'Programa Drench'!$B$6:$AA$182,MATCH(L$2,'Programa Drench'!$B$5:$AA$5,0),FALSE)),0) -> Flutrialaq | M3: =IFERROR((VLOOKUP($H3,'Programa Drench'!$B$6:$AA$182,MATCH(M$2,'Programa Drench'!$B$5:$AA$5,0),FALSE)*N3),0) -> 108 | N3: =IFERROR(ROUND((K3*$I3),-1),0) -> 270 | O3: =IFERROR(ROUND(IF($D3="SSJ",(VLOOKUP($H3,'Programa Drench'!$B$6:$AA$182,MATCH(O$2,'Programa Drench'!$B$5:$AA$5,0),FALSE)),VLOOKUP($H3,'Programa Drench'!$B$6:$AA$182,MATCH(O$2,'Programa Drench'!$B$5:$AA$5,0),FALSE)),1),0) -> 7 | P3: =IFERROR((VLOOKUP($H3,'Programa Drench'!$B$6:$AA$182,MATCH(P$2,'Programa Drench'!$B$5:$AA$5,0),FALSE)),0) -> Agral | Q3: =IFERROR((VLOOKUP($H3,'Programa Drench'!$B$6:$AA$182,MATCH(Q$2,'Programa Drench'!$B$5:$AA$5,0),FALSE)*R3),0) -> 54 | R3: =IFERROR(ROUND((O3*$I3),-1),0) -> 270 | S3: =IFERROR(ROUND(IF($D3="SSJ",(VLOOKUP($H3,'Programa Drench'!$B$6:$AA$182,MATCH(S$2,'Programa Drench'!$B$5:$AA$5,0),FALSE)),VLOOKUP($H3,'Programa Drench'!$B$6:$AA$182,MATCH(S$2,'Programa Drench'!$B$5:$AA$5,0),FALSE)),1),0) -> 0 | T3: =IFERROR((VLOOKUP($H3,'Programa Drench'!$B$6:$AA$182,MATCH(T$2,'Programa Drench'!$B$5:$AA$5,0),FALSE)),0) -> 0 | U3: =IFERROR((VLOOKUP($H3,'Programa Drench'!$B$6:$AA$182,MATCH(U$2,'Programa Drench'!$B$5:$AA$5,0),FALSE)*V3),0) -> 0 | V3: =IFERROR(ROUND((S3*$I3),-1),0) -> 0 | W3: =IFERROR(ROUND(IF($D3="SSJ",(VLOOKUP($H3,'Programa Drench'!$B$6:$AA$182,MATCH(W$2,'Programa Drench'!$B$5:$AA$5,0),FALSE)),VLOOKUP($H3,'Programa Drench'!$B$6:$AA$182,MATCH(W$2,'Programa Drench'!$B$5:$AA$5,0),FALSE)),1),0) -> 0 | X3: =IFERROR((VLOOKUP($H3,'Programa Drench'!$B$6:$AA$182,MATCH(X$2,'Programa Drench'!$B$5:$AA$5,0),FALSE)),0) -> 0 | Y3: =IFERROR((VLOOKUP($H3,'Programa Drench'!$B$6:$AA$182,MATCH(Y$2,'Programa Drench'!$B$5:$AA$5,0),FALSE)*Z3),0) -> 0 | Z3: =IFERROR(ROUND((W3*$I3),-1),0) -> 0 | AA3: =IFERROR(ROUND(IF($D3="SSJ",(VLOOKUP($H3,'Programa Drench'!$B$6:$AA$182,MATCH(AA$2,'Programa Drench'!$B$5:$AA$5,0),FALSE)),VLOOKUP($H3,'Programa Drench'!$B$6:$AA$182,MATCH(AA$2,'Programa Drench'!$B$5:$AA$5,0),FALSE)),1),0) -> 0 | AB3: =IFERROR((VLOOKUP($H3,'Programa Drench'!$B$6:$AA$182,MATCH(AB$2,'Programa Drench'!$B$5:$AA$5,0),FALSE)),0) -> 0 | AC3: =IFERROR((VLOOKUP($H3,'Programa Drench'!$B$6:$AA$182,MATCH(AC$2,'Programa Drench'!$B$5:$AA$5,0),FALSE)*$I3),0) -> 0 | AD3: =IFERROR(ROUND((AA3*$I3),-1),0) -> 0 | AE3: =IFERROR(ROUND((VLOOKUP($H3,'Programa Drench'!$B$6:$AA$182,MATCH(AE$2,'Programa Drench'!$B$5:$AA$5,0),FALSE)),-1),0) -> 0 | AF3: =IFERROR((VLOOKUP($H3,'Programa Drench'!$B$6:$AA$182,MATCH(AF$2,'Programa Drench'!$B$5:$AA$5,0),FALSE)),0) -> 0 | AG3: =IFERROR((VLOOKUP($H3,'Programa Drench'!$B$6:$AA$182,MATCH(AG$2,'Programa Drench'!$B$5:$AA$5,0),FALSE)*AH3),0) -> 0 | AH3: =IFERROR(ROUND((VLOOKUP($H3,'Programa Drench'!$B$6:$AA$182,MATCH(AH$2,'Programa Drench'!$B$5:$AA$5,0),FALSE)*$I3),-1),0) -> 0 | AI3: =IFERROR((VLOOKUP($H3,'Programa Drench'!$B$6:$AA$182,MATCH(AI$2,'Programa Drench'!$B$5:$AA$5,0),FALSE)),0) -> 0.6
A4: =IF(($J$1-C4)>=52,($J$1-C4-100+52+1),($J$1-C4+1)) -> 12 | B4: 5 | C4: 2608 | D4: CV | E4: P3 | F4: XL | G4: =MID(E4,1,1) -> P | H4: =CONCATENATE(A4," ",G4," ",F4) -> 12 P XL | I4: =IF(D4="MM1",VLOOKUP($B4,'Inf Bloques'!$A$1:$K$453,11,FALSE)*1,VLOOKUP($B4,'Inf Bloques'!$A$1:$K$453,11,FALSE)) -> 33.28705 | J4: =I4/9 -> 3.6985611 | K4: =IFERROR(ROUND(IF($D4="SSJ",(VLOOKUP($H4,'Programa Drench'!$B$6:$AA$182,MATCH(K$2,'Programa Drench'!$B$5:$AA$5,0),FALSE)),VLOOKUP($H4,'Programa Drench'!$B$6:$AA$182,MATCH(K$2,'Programa Drench'!$B$5:$AA$5,0),FALSE)),1),0) -> 50 | L4: =IFERROR((VLOOKUP($H4,'Programa Drench'!$B$6:$AA$182,MATCH(L$2,'Programa Drench'!$B$5:$AA$5,0),FALSE)),0) -> ALCAPLANT | M4: =IFERROR((VLOOKUP($H4,'Programa Drench'!$B$6:$AA$182,MATCH(M$2,'Programa Drench'!$B$5:$AA$5,0),FALSE)*N4),0) -> 1826 | N4: =IFERROR(ROUND((K4*$I4),-1),0) -> 1660 | O4: =IFERROR(ROUND(IF($D4="SSJ",(VLOOKUP($H4,'Programa Drench'!$B$6:$AA$182,MATCH(O$2,'Programa Drench'!$B$5:$AA$5,0),FALSE)),VLOOKUP($H4,'Programa Drench'!$B$6:$AA$182,MATCH(O$2,'Programa Drench'!$B$5:$AA$5,0),FALSE)),1),0) -> 0 | P4: =IFERROR((VLOOKUP($H4,'Programa Drench'!$B$6:$AA$182,MATCH(P$2,'Programa Drench'!$B$5:$AA$5,0),FALSE)),0) -> 0 | Q4: =IFERROR((VLOOKUP($H4,'Programa Drench'!$B$6:$AA$182,MATCH(Q$2,'Programa Drench'!$B$5:$AA$5,0),FALSE)*R4),0) -> 0 | R4: =IFERROR(ROUND((O4*$I4),-1),0) -> 0 | S4: =IFERROR(ROUND(IF($D4="SSJ",(VLOOKUP($H4,'Programa Drench'!$B$6:$AA$182,MATCH(S$2,'Programa Drench'!$B$5:$AA$5,0),FALSE)),VLOOKUP($H4,'Programa Drench'!$B$6:$AA$182,MATCH(S$2,'Programa Drench'!$B$5:$AA$5,0),FALSE)),1),0) -> 0 | T4: =IFERROR((VLOOKUP($H4,'Programa Drench'!$B$6:$AA$182,MATCH(T$2,'Programa Drench'!$B$5:$AA$5,0),FALSE)),0) -> 0 | U4: =IFERROR((VLOOKUP($H4,'Programa Drench'!$B$6:$AA$182,MATCH(U$2,'Programa Drench'!$B$5:$AA$5,0),FALSE)*V4),0) -> 0 | V4: =IFERROR(ROUND((S4*$I4),-1),0) -> 0 | W4: =IFERROR(ROUND(IF($D4="SSJ",(VLOOKUP($H4,'Programa Drench'!$B$6:$AA$182,MATCH(W$2,'Programa Drench'!$B$5:$AA$5,0),FALSE)),VLOOKUP($H4,'Programa Drench'!$B$6:$AA$182,MATCH(W$2,'Programa Drench'!$B$5:$AA$5,0),FALSE)),1),0) -> 0 | X4: =IFERROR((VLOOKUP($H4,'Programa Drench'!$B$6:$AA$182,MATCH(X$2,'Programa Drench'!$B$5:$AA$5,0),FALSE)),0) -> 0 | Y4: =IFERROR((VLOOKUP($H4,'Programa Drench'!$B$6:$AA$182,MATCH(Y$2,'Programa Drench'!$B$5:$AA$5,0),FALSE)*Z4),0) -> 0 | Z4: =IFERROR(ROUND((W4*$I4),-1),0) -> 0 | AA4: =IFERROR(ROUND(IF($D4="SSJ",(VLOOKUP($H4,'Programa Drench'!$B$6:$AA$182,MATCH(AA$2,'Programa Drench'!$B$5:$AA$5,0),FALSE)),VLOOKUP($H4,'Programa Drench'!$B$6:$AA$182,MATCH(AA$2,'Programa Drench'!$B$5:$AA$5,0),FALSE)),1),0) -> 0 | AB4: =IFERROR((VLOOKUP($H4,'Programa Drench'!$B$6:$AA$182,MATCH(AB$2,'Programa Drench'!$B$5:$AA$5,0),FALSE)),0) -> 0 | AC4: =IFERROR((VLOOKUP($H4,'Programa Drench'!$B$6:$AA$182,MATCH(AC$2,'Programa Drench'!$B$5:$AA$5,0),FALSE)*$I4),0) -> 0 | AD4: =IFERROR(ROUND((AA4*$I4),-1),0) -> 0 | AE4: =IFERROR(ROUND((VLOOKUP($H4,'Programa Drench'!$B$6:$AA$182,MATCH(AE$2,'Programa Drench'!$B$5:$AA$5,0),FALSE)),-1),0) -> 0 | AF4: =IFERROR((VLOOKUP($H4,'Programa Drench'!$B$6:$AA$182,MATCH(AF$2,'Programa Drench'!$B$5:$AA$5,0),FALSE)),0) -> 0 | AG4: =IFERROR((VLOOKUP($H4,'Programa Drench'!$B$6:$AA$182,MATCH(AG$2,'Programa Drench'!$B$5:$AA$5,0),FALSE)*AH4),0) -> 0 | AH4: =IFERROR(ROUND((VLOOKUP($H4,'Programa Drench'!$B$6:$AA$182,MATCH(AH$2,'Programa Drench'!$B$5:$AA$5,0),FALSE)*$I4),-1),0) -> 0 | AI4: =IFERROR((VLOOKUP($H4,'Programa Drench'!$B$6:$AA$182,MATCH(AI$2,'Programa Drench'!$B$5:$AA$5,0),FALSE)),0) -> 1.1
A5: =IF(($J$1-C5)>=52,($J$1-C5-100+52+1),($J$1-C5+1)) -> 12 | B5: 15 | C5: 2608 | D5: CV | E5: P3 | F5: XL | G5: =MID(E5,1,1) -> P | H5: =CONCATENATE(A5," ",G5," ",F5) -> 12 P XL | I5: =IF(D5="MM1",VLOOKUP($B5,'Inf Bloques'!$A$1:$K$453,11,FALSE)*1,VLOOKUP($B5,'Inf Bloques'!$A$1:$K$453,11,FALSE)) -> 39.546833 | J5: =I5/9 -> 4.3940926 | K5: =IFERROR(ROUND(IF($D5="SSJ",(VLOOKUP($H5,'Programa Drench'!$B$6:$AA$182,MATCH(K$2,'Programa Drench'!$B$5:$AA$5,0),FALSE)),VLOOKUP($H5,'Programa Drench'!$B$6:$AA$182,MATCH(K$2,'Programa Drench'!$B$5:$AA$5,0),FALSE)),1),0) -> 50 | L5: =IFERROR((VLOOKUP($H5,'Programa Drench'!$B$6:$AA$182,MATCH(L$2,'Programa Drench'!$B$5:$AA$5,0),FALSE)),0) -> ALCAPLANT | M5: =IFERROR((VLOOKUP($H5,'Programa Drench'!$B$6:$AA$182,MATCH(M$2,'Programa Drench'!$B$5:$AA$5,0),FALSE)*N5),0) -> 2178 | N5: =IFERROR(ROUND((K5*$I5),-1),0) -> 1980 | O5: =IFERROR(ROUND(IF($D5="SSJ",(VLOOKUP($H5,'Programa Drench'!$B$6:$AA$182,MATCH(O$2,'Programa Drench'!$B$5:$AA$5,0),FALSE)),VLOOKUP($H5,'Programa Drench'!$B$6:$AA$182,MATCH(O$2,'Programa Drench'!$B$5:$AA$5,0),FALSE)),1),0) -> 0 | P5: =IFERROR((VLOOKUP($H5,'Programa Drench'!$B$6:$AA$182,MATCH(P$2,'Programa Drench'!$B$5:$AA$5,0),FALSE)),0) -> 0 | Q5: =IFERROR((VLOOKUP($H5,'Programa Drench'!$B$6:$AA$182,MATCH(Q$2,'Programa Drench'!$B$5:$AA$5,0),FALSE)*R5),0) -> 0 | R5: =IFERROR(ROUND((O5*$I5),-1),0) -> 0 | S5: =IFERROR(ROUND(IF($D5="SSJ",(VLOOKUP($H5,'Programa Drench'!$B$6:$AA$182,MATCH(S$2,'Programa Drench'!$B$5:$AA$5,0),FALSE)),VLOOKUP($H5,'Programa Drench'!$B$6:$AA$182,MATCH(S$2,'Programa Drench'!$B$5:$AA$5,0),FALSE)),1),0) -> 0 | T5: =IFERROR((VLOOKUP($H5,'Programa Drench'!$B$6:$AA$182,MATCH(T$2,'Programa Drench'!$B$5:$AA$5,0),FALSE)),0) -> 0 | U5: =IFERROR((VLOOKUP($H5,'Programa Drench'!$B$6:$AA$182,MATCH(U$2,'Programa Drench'!$B$5:$AA$5,0),FALSE)*V5),0) -> 0 | V5: =IFERROR(ROUND((S5*$I5),-1),0) -> 0 | W5: =IFERROR(ROUND(IF($D5="SSJ",(VLOOKUP($H5,'Programa Drench'!$B$6:$AA$182,MATCH(W$2,'Programa Drench'!$B$5:$AA$5,0),FALSE)),VLOOKUP($H5,'Programa Drench'!$B$6:$AA$182,MATCH(W$2,'Programa Drench'!$B$5:$AA$5,0),FALSE)),1),0) -> 0 | X5: =IFERROR((VLOOKUP($H5,'Programa Drench'!$B$6:$AA$182,MATCH(X$2,'Programa Drench'!$B$5:$AA$5,0),FALSE)),0) -> 0 | Y5: =IFERROR((VLOOKUP($H5,'Programa Drench'!$B$6:$AA$182,MATCH(Y$2,'Programa Drench'!$B$5:$AA$5,0),FALSE)*Z5),0) -> 0 | Z5: =IFERROR(ROUND((W5*$I5),-1),0) -> 0 | AA5: =IFERROR(ROUND(IF($D5="SSJ",(VLOOKUP($H5,'Programa Drench'!$B$6:$AA$182,MATCH(AA$2,'Programa Drench'!$B$5:$AA$5,0),FALSE)),VLOOKUP($H5,'Programa Drench'!$B$6:$AA$182,MATCH(AA$2,'Programa Drench'!$B$5:$AA$5,0),FALSE)),1),0) -> 0 | AB5: =IFERROR((VLOOKUP($H5,'Programa Drench'!$B$6:$AA$182,MATCH(AB$2,'Programa Drench'!$B$5:$AA$5,0),FALSE)),0) -> 0 | AC5: =IFERROR((VLOOKUP($H5,'Programa Drench'!$B$6:$AA$182,MATCH(AC$2,'Programa Drench'!$B$5:$AA$5,0),FALSE)*$I5),0) -> 0 | AD5: =IFERROR(ROUND((AA5*$I5),-1),0) -> 0 | AE5: =IFERROR(ROUND((VLOOKUP($H5,'Programa Drench'!$B$6:$AA$182,MATCH(AE$2,'Programa Drench'!$B$5:$AA$5,0),FALSE)),-1),0) -> 0 | AF5: =IFERROR((VLOOKUP($H5,'Programa Drench'!$B$6:$AA$182,MATCH(AF$2,'Programa Drench'!$B$5:$AA$5,0),FALSE)),0) -> 0 | AG5: =IFERROR((VLOOKUP($H5,'Programa Drench'!$B$6:$AA$182,MATCH(AG$2,'Programa Drench'!$B$5:$AA$5,0),FALSE)*AH5),0) -> 0 | AH5: =IFERROR(ROUND((VLOOKUP($H5,'Programa Drench'!$B$6:$AA$182,MATCH(AH$2,'Programa Drench'!$B$5:$AA$5,0),FALSE)*$I5),-1),0) -> 0 | AI5: =IFERROR((VLOOKUP($H5,'Programa Drench'!$B$6:$AA$182,MATCH(AI$2,'Programa Drench'!$B$5:$AA$5,0),FALSE)),0) -> 1.1
A6: =IF(($J$1-C6)>=52,($J$1-C6-100+52+1),($J$1-C6+1)) -> 12 | B6: 22 | C6: 2608 | D6: CV | E6: S | F6: XL | G6: =MID(E6,1,1) -> S | H6: =CONCATENATE(A6," ",G6," ",F6) -> 12 S XL | I6: =IF(D6="MM1",VLOOKUP($B6,'Inf Bloques'!$A$1:$K$453,11,FALSE)*1,VLOOKUP($B6,'Inf Bloques'!$A$1:$K$453,11,FALSE)) -> 39.072 | J6: =I6/9 -> 4.3413333 | K6: =IFERROR(ROUND(IF($D6="SSJ",(VLOOKUP($H6,'Programa Drench'!$B$6:$AA$182,MATCH(K$2,'Programa Drench'!$B$5:$AA$5,0),FALSE)),VLOOKUP($H6,'Programa Drench'!$B$6:$AA$182,MATCH(K$2,'Programa Drench'!$B$5:$AA$5,0),FALSE)),1),0) -> 7 | L6: =IFERROR((VLOOKUP($H6,'Programa Drench'!$B$6:$AA$182,MATCH(L$2,'Programa Drench'!$B$5:$AA$5,0),FALSE)),0) -> Sulfex | M6: =IFERROR((VLOOKUP($H6,'Programa Drench'!$B$6:$AA$182,MATCH(M$2,'Programa Drench'!$B$5:$AA$5,0),FALSE)*N6),0) -> 405 | N6: =IFERROR(ROUND((K6*$I6),-1),0) -> 270 | O6: =IFERROR(ROUND(IF($D6="SSJ",(VLOOKUP($H6,'Programa Drench'!$B$6:$AA$182,MATCH(O$2,'Programa Drench'!$B$5:$AA$5,0),FALSE)),VLOOKUP($H6,'Programa Drench'!$B$6:$AA$182,MATCH(O$2,'Programa Drench'!$B$5:$AA$5,0),FALSE)),1),0) -> 7 | P6: =IFERROR((VLOOKUP($H6,'Programa Drench'!$B$6:$AA$182,MATCH(P$2,'Programa Drench'!$B$5:$AA$5,0),FALSE)),0) -> Agral | Q6: =IFERROR((VLOOKUP($H6,'Programa Drench'!$B$6:$AA$182,MATCH(Q$2,'Programa Drench'!$B$5:$AA$5,0),FALSE)*R6),0) -> 54 | R6: =IFERROR(ROUND((O6*$I6),-1),0) -> 270 | S6: =IFERROR(ROUND(IF($D6="SSJ",(VLOOKUP($H6,'Programa Drench'!$B$6:$AA$182,MATCH(S$2,'Programa Drench'!$B$5:$AA$5,0),FALSE)),VLOOKUP($H6,'Programa Drench'!$B$6:$AA$182,MATCH(S$2,'Programa Drench'!$B$5:$AA$5,0),FALSE)),1),0) -> 0 | T6: =IFERROR((VLOOKUP($H6,'Programa Drench'!$B$6:$AA$182,MATCH(T$2,'Programa Drench'!$B$5:$AA$5,0),FALSE)),0) -> 0 | U6: =IFERROR((VLOOKUP($H6,'Programa Drench'!$B$6:$AA$182,MATCH(U$2,'Programa Drench'!$B$5:$AA$5,0),FALSE)*V6),0) -> 0 | V6: =IFERROR(ROUND((S6*$I6),-1),0) -> 0 | W6: =IFERROR(ROUND(IF($D6="SSJ",(VLOOKUP($H6,'Programa Drench'!$B$6:$AA$182,MATCH(W$2,'Programa Drench'!$B$5:$AA$5,0),FALSE)),VLOOKUP($H6,'Programa Drench'!$B$6:$AA$182,MATCH(W$2,'Programa Drench'!$B$5:$AA$5,0),FALSE)),1),0) -> 0 | X6: =IFERROR((VLOOKUP($H6,'Programa Drench'!$B$6:$AA$182,MATCH(X$2,'Programa Drench'!$B$5:$AA$5,0),FALSE)),0) -> 0 | Y6: =IFERROR((VLOOKUP($H6,'Programa Drench'!$B$6:$AA$182,MATCH(Y$2,'Programa Drench'!$B$5:$AA$5,0),FALSE)*Z6),0) -> 0 | Z6: =IFERROR(ROUND((W6*$I6),-1),0) -> 0 | AA6: =IFERROR(ROUND(IF($D6="SSJ",(VLOOKUP($H6,'Programa Drench'!$B$6:$AA$182,MATCH(AA$2,'Programa Drench'!$B$5:$AA$5,0),FALSE)),VLOOKUP($H6,'Programa Drench'!$B$6:$AA$182,MATCH(AA$2,'Programa Drench'!$B$5:$AA$5,0),FALSE)),1),0) -> 0 | AB6: =IFERROR((VLOOKUP($H6,'Programa Drench'!$B$6:$AA$182,MATCH(AB$2,'Programa Drench'!$B$5:$AA$5,0),FALSE)),0) -> 0 | AC6: =IFERROR((VLOOKUP($H6,'Programa Drench'!$B$6:$AA$182,MATCH(AC$2,'Programa Drench'!$B$5:$AA$5,0),FALSE)*$I6),0) -> 0 | AD6: =IFERROR(ROUND((AA6*$I6),-1),0) -> 0 | AE6: =IFERROR(ROUND((VLOOKUP($H6,'Programa Drench'!$B$6:$AA$182,MATCH(AE$2,'Programa Drench'!$B$5:$AA$5,0),FALSE)),-1),0) -> 0 | AF6: =IFERROR((VLOOKUP($H6,'Programa Drench'!$B$6:$AA$182,MATCH(AF$2,'Programa Drench'!$B$5:$AA$5,0),FALSE)),0) -> 0 | AG6: =IFERROR((VLOOKUP($H6,'Programa Drench'!$B$6:$AA$182,MATCH(AG$2,'Programa Drench'!$B$5:$AA$5,0),FALSE)*AH6),0) -> 0 | AH6: =IFERROR(ROUND((VLOOKUP($H6,'Programa Drench'!$B$6:$AA$182,MATCH(AH$2,'Programa Drench'!$B$5:$AA$5,0),FALSE)*$I6),-1),0) -> 0 | AI6: =IFERROR((VLOOKUP($H6,'Programa Drench'!$B$6:$AA$182,MATCH(AI$2,'Programa Drench'!$B$5:$AA$5,0),FALSE)),0) -> 1.7
A7: =IF(($J$1-C7)>=52,($J$1-C7-100+52+1),($J$1-C7+1)) -> 12 | B7: 23 | C7: 2608 | D7: CV | E7: P3 | F7: XL | G7: =MID(E7,1,1) -> P | H7: =CONCATENATE(A7," ",G7," ",F7) -> 12 P XL | I7: =IF(D7="MM1",VLOOKUP($B7,'Inf Bloques'!$A$1:$K$453,11,FALSE)*1,VLOOKUP($B7,'Inf Bloques'!$A$1:$K$453,11,FALSE)) -> 38.97565 | J7: =I7/9 -> 4.3306278 | K7: =IFERROR(ROUND(IF($D7="SSJ",(VLOOKUP($H7,'Programa Drench'!$B$6:$AA$182,MATCH(K$2,'Programa Drench'!$B$5:$AA$5,0),FALSE)),VLOOKUP($H7,'Programa Drench'!$B$6:$AA$182,MATCH(K$2,'Programa Drench'!$B$5:$AA$5,0),FALSE)),1),0) -> 50 | L7: =IFERROR((VLOOKUP($H7,'Programa Drench'!$B$6:$AA$182,MATCH(L$2,'Programa Drench'!$B$5:$AA$5,0),FALSE)),0) -> ALCAPLANT | M7: =IFERROR((VLOOKUP($H7,'Programa Drench'!$B$6:$AA$182,MATCH(M$2,'Programa Drench'!$B$5:$AA$5,0),FALSE)*N7),0) -> 2145 | N7: =IFERROR(ROUND((K7*$I7),-1),0) -> 1950 | O7: =IFERROR(ROUND(IF($D7="SSJ",(VLOOKUP($H7,'Programa Drench'!$B$6:$AA$182,MATCH(O$2,'Programa Drench'!$B$5:$AA$5,0),FALSE)),VLOOKUP($H7,'Programa Drench'!$B$6:$AA$182,MATCH(O$2,'Programa Drench'!$B$5:$AA$5,0),FALSE)),1),0) -> 0 | P7: =IFERROR((VLOOKUP($H7,'Programa Drench'!$B$6:$AA$182,MATCH(P$2,'Programa Drench'!$B$5:$AA$5,0),FALSE)),0) -> 0 | Q7: =IFERROR((VLOOKUP($H7,'Programa Drench'!$B$6:$AA$182,MATCH(Q$2,'Programa Drench'!$B$5:$AA$5,0),FALSE)*R7),0) -> 0 | R7: =IFERROR(ROUND((O7*$I7),-1),0) -> 0 | S7: =IFERROR(ROUND(IF($D7="SSJ",(VLOOKUP($H7,'Programa Drench'!$B$6:$AA$182,MATCH(S$2,'Programa Drench'!$B$5:$AA$5,0),FALSE)),VLOOKUP($H7,'Programa Drench'!$B$6:$AA$182,MATCH(S$2,'Programa Drench'!$B$5:$AA$5,0),FALSE)),1),0) -> 0 | T7: =IFERROR((VLOOKUP($H7,'Programa Drench'!$B$6:$AA$182,MATCH(T$2,'Programa Drench'!$B$5:$AA$5,0),FALSE)),0) -> 0 | U7: =IFERROR((VLOOKUP($H7,'Programa Drench'!$B$6:$AA$182,MATCH(U$2,'Programa Drench'!$B$5:$AA$5,0),FALSE)*V7),0) -> 0 | V7: =IFERROR(ROUND((S7*$I7),-1),0) -> 0 | W7: =IFERROR(ROUND(IF($D7="SSJ",(VLOOKUP($H7,'Programa Drench'!$B$6:$AA$182,MATCH(W$2,'Programa Drench'!$B$5:$AA$5,0),FALSE)),VLOOKUP($H7,'Programa Drench'!$B$6:$AA$182,MATCH(W$2,'Programa Drench'!$B$5:$AA$5,0),FALSE)),1),0) -> 0 | X7: =IFERROR((VLOOKUP($H7,'Programa Drench'!$B$6:$AA$182,MATCH(X$2,'Programa Drench'!$B$5:$AA$5,0),FALSE)),0) -> 0 | Y7: =IFERROR((VLOOKUP($H7,'Programa Drench'!$B$6:$AA$182,MATCH(Y$2,'Programa Drench'!$B$5:$AA$5,0),FALSE)*Z7),0) -> 0 | Z7: =IFERROR(ROUND((W7*$I7),-1),0) -> 0 | AA7: =IFERROR(ROUND(IF($D7="SSJ",(VLOOKUP($H7,'Programa Drench'!$B$6:$AA$182,MATCH(AA$2,'Programa Drench'!$B$5:$AA$5,0),FALSE)),VLOOKUP($H7,'Programa Drench'!$B$6:$AA$182,MATCH(AA$2,'Programa Drench'!$B$5:$AA$5,0),FALSE)),1),0) -> 0 | AB7: =IFERROR((VLOOKUP($H7,'Programa Drench'!$B$6:$AA$182,MATCH(AB$2,'Programa Drench'!$B$5:$AA$5,0),FALSE)),0) -> 0 | AC7: =IFERROR((VLOOKUP($H7,'Programa Drench'!$B$6:$AA$182,MATCH(AC$2,'Programa Drench'!$B$5:$AA$5,0),FALSE)*$I7),0) -> 0 | AD7: =IFERROR(ROUND((AA7*$I7),-1),0) -> 0 | AE7: =IFERROR(ROUND((VLOOKUP($H7,'Programa Drench'!$B$6:$AA$182,MATCH(AE$2,'Programa Drench'!$B$5:$AA$5,0),FALSE)),-1),0) -> 0 | AF7: =IFERROR((VLOOKUP($H7,'Programa Drench'!$B$6:$AA$182,MATCH(AF$2,'Programa Drench'!$B$5:$AA$5,0),FALSE)),0) -> 0 | AG7: =IFERROR((VLOOKUP($H7,'Programa Drench'!$B$6:$AA$182,MATCH(AG$2,'Programa Drench'!$B$5:$AA$5,0),FALSE)*AH7),0) -> 0 | AH7: =IFERROR(ROUND((VLOOKUP($H7,'Programa Drench'!$B$6:$AA$182,MATCH(AH$2,'Programa Drench'!$B$5:$AA$5,0),FALSE)*$I7),-1),0) -> 0 | AI7: =IFERROR((VLOOKUP($H7,'Programa Drench'!$B$6:$AA$182,MATCH(AI$2,'Programa Drench'!$B$5:$AA$5,0),FALSE)),0) -> 1.1
A8: =IF(($J$1-C8)>=52,($J$1-C8-100+52+1),($J$1-C8+1)) -> 11 | B8: 4 | C8: 2609 | D8: CV | E8: P3 | F8: XL | G8: =MID(E8,1,1) -> P | H8: =CONCATENATE(A8," ",G8," ",F8) -> 11 P XL | I8: =IF(D8="MM1",VLOOKUP($B8,'Inf Bloques'!$A$1:$K$453,11,FALSE)*1,VLOOKUP($B8,'Inf Bloques'!$A$1:$K$453,11,FALSE)) -> 31.331 | J8: =I8/9 -> 3.4812222 | K8: =IFERROR(ROUND(IF($D8="SSJ",(VLOOKUP($H8,'Programa Drench'!$B$6:$AA$182,MATCH(K$2,'Programa Drench'!$B$5:$AA$5,0),FALSE)),VLOOKUP($H8,'Programa Drench'!$B$6:$AA$182,MATCH(K$2,'Programa Drench'!$B$5:$AA$5,0),FALSE)),1),0) -> 7 | L8: =IFERROR((VLOOKUP($H8,'Programa Drench'!$B$6:$AA$182,MATCH(L$2,'Programa Drench'!$B$5:$AA$5,0),FALSE)),0) -> Sulfex | M8: =IFERROR((VLOOKUP($H8,'Programa Drench'!$B$6:$AA$182,MATCH(M$2,'Programa Drench'!$B$5:$AA$5,0),FALSE)*N8),0) -> 330 | N8: =IFERROR(ROUND((K8*$I8),-1),0) -> 220 | O8: =IFERROR(ROUND(IF($D8="SSJ",(VLOOKUP($H8,'Programa Drench'!$B$6:$AA$182,MATCH(O$2,'Programa Drench'!$B$5:$AA$5,0),FALSE)),VLOOKUP($H8,'Programa Drench'!$B$6:$AA$182,MATCH(O$2,'Programa Drench'!$B$5:$AA$5,0),FALSE)),1),0) -> 7 | P8: =IFERROR((VLOOKUP($H8,'Programa Drench'!$B$6:$AA$182,MATCH(P$2,'Programa Drench'!$B$5:$AA$5,0),FALSE)),0) -> Agral | Q8: =IFERROR((VLOOKUP($H8,'Programa Drench'!$B$6:$AA$182,MATCH(Q$2,'Programa Drench'!$B$5:$AA$5,0),FALSE)*R8),0) -> 44 | R8: =IFERROR(ROUND((O8*$I8),-1),0) -> 220 | S8: =IFERROR(ROUND(IF($D8="SSJ",(VLOOKUP($H8,'Programa Drench'!$B$6:$AA$182,MATCH(S$2,'Programa Drench'!$B$5:$AA$5,0),FALSE)),VLOOKUP($H8,'Programa Drench'!$B$6:$AA$182,MATCH(S$2,'Programa Drench'!$B$5:$AA$5,0),FALSE)),1),0) -> 0 | T8: =IFERROR((VLOOKUP($H8,'Programa Drench'!$B$6:$AA$182,MATCH(T$2,'Programa Drench'!$B$5:$AA$5,0),FALSE)),0) -> 0 | U8: =IFERROR((VLOOKUP($H8,'Programa Drench'!$B$6:$AA$182,MATCH(U$2,'Programa Drench'!$B$5:$AA$5,0),FALSE)*V8),0) -> 0 | V8: =IFERROR(ROUND((S8*$I8),-1),0) -> 0 | W8: =IFERROR(ROUND(IF($D8="SSJ",(VLOOKUP($H8,'Programa Drench'!$B$6:$AA$182,MATCH(W$2,'Programa Drench'!$B$5:$AA$5,0),FALSE)),VLOOKUP($H8,'Programa Drench'!$B$6:$AA$182,MATCH(W$2,'Programa Drench'!$B$5:$AA$5,0),FALSE)),1),0) -> 0 | X8: =IFERROR((VLOOKUP($H8,'Programa Drench'!$B$6:$AA$182,MATCH(X$2,'Programa Drench'!$B$5:$AA$5,0),FALSE)),0) -> 0 | Y8: =IFERROR((VLOOKUP($H8,'Programa Drench'!$B$6:$AA$182,MATCH(Y$2,'Programa Drench'!$B$5:$AA$5,0),FALSE)*Z8),0) -> 0 | Z8: =IFERROR(ROUND((W8*$I8),-1),0) -> 0 | AA8: =IFERROR(ROUND(IF($D8="SSJ",(VLOOKUP($H8,'Programa Drench'!$B$6:$AA$182,MATCH(AA$2,'Programa Drench'!$B$5:$AA$5,0),FALSE)),VLOOKUP($H8,'Programa Drench'!$B$6:$AA$182,MATCH(AA$2,'Programa Drench'!$B$5:$AA$5,0),FALSE)),1),0) -> 0 | AB8: =IFERROR((VLOOKUP($H8,'Programa Drench'!$B$6:$AA$182,MATCH(AB$2,'Programa Drench'!$B$5:$AA$5,0),FALSE)),0) -> 0 | AC8: =IFERROR((VLOOKUP($H8,'Programa Drench'!$B$6:$AA$182,MATCH(AC$2,'Programa Drench'!$B$5:$AA$5,0),FALSE)*$I8),0) -> 0 | AD8: =IFERROR(ROUND((AA8*$I8),-1),0) -> 0 | AE8: =IFERROR(ROUND((VLOOKUP($H8,'Programa Drench'!$B$6:$AA$182,MATCH(AE$2,'Programa Drench'!$B$5:$AA$5,0),FALSE)),-1),0) -> 0 | AF8: =IFERROR((VLOOKUP($H8,'Programa Drench'!$B$6:$AA$182,MATCH(AF$2,'Programa Drench'!$B$5:$AA$5,0),FALSE)),0) -> 0 | AG8: =IFERROR((VLOOKUP($H8,'Programa Drench'!$B$6:$AA$182,MATCH(AG$2,'Programa Drench'!$B$5:$AA$5,0),FALSE)*AH8),0) -> 0 | AH8: =IFERROR(ROUND((VLOOKUP($H8,'Programa Drench'!$B$6:$AA$182,MATCH(AH$2,'Programa Drench'!$B$5:$AA$5,0),FALSE)*$I8),-1),0) -> 0 | AI8: =IFERROR((VLOOKUP($H8,'Programa Drench'!$B$6:$AA$182,MATCH(AI$2,'Programa Drench'!$B$5:$AA$5,0),FALSE)),0) -> 1.7
A9: =IF(($J$1-C9)>=52,($J$1-C9-100+52+1),($J$1-C9+1)) -> 10 | B9: 9 | C9: 2610 | D9: CV | E9: P3 | F9: XL | G9: =MID(E9,1,1) -> P | H9: =CONCATENATE(A9," ",G9," ",F9) -> 10 P XL | I9: =IF(D9="MM1",VLOOKUP($B9,'Inf Bloques'!$A$1:$K$453,11,FALSE)*1,VLOOKUP($B9,'Inf Bloques'!$A$1:$K$453,11,FALSE)) -> 39.519683 | J9: =I9/9 -> 4.3910759 | K9: =IFERROR(ROUND(IF($D9="SSJ",(VLOOKUP($H9,'Programa Drench'!$B$6:$AA$182,MATCH(K$2,'Programa Drench'!$B$5:$AA$5,0),FALSE)),VLOOKUP($H9,'Programa Drench'!$B$6:$AA$182,MATCH(K$2,'Programa Drench'!$B$5:$AA$5,0),FALSE)),1),0) -> 10 | L9: =IFERROR((VLOOKUP($H9,'Programa Drench'!$B$6:$AA$182,MATCH(L$2,'Programa Drench'!$B$5:$AA$5,0),FALSE)),0) -> Bac | M9: =IFERROR((VLOOKUP($H9,'Programa Drench'!$B$6:$AA$182,MATCH(M$2,'Programa Drench'!$B$5:$AA$5,0),FALSE)*N9),0) -> 800 | N9: =IFERROR(ROUND((K9*$I9),-1),0) -> 400 | O9: =IFERROR(ROUND(IF($D9="SSJ",(VLOOKUP($H9,'Programa Drench'!$B$6:$AA$182,MATCH(O$2,'Programa Drench'!$B$5:$AA$5,0),FALSE)),VLOOKUP($H9,'Programa Drench'!$B$6:$AA$182,MATCH(O$2,'Programa Drench'!$B$5:$AA$5,0),FALSE)),1),0) -> 10 | P9: =IFERROR((VLOOKUP($H9,'Programa Drench'!$B$6:$AA$182,MATCH(P$2,'Programa Drench'!$B$5:$AA$5,0),FALSE)),0) -> Agral | Q9: =IFERROR((VLOOKUP($H9,'Programa Drench'!$B$6:$AA$182,MATCH(Q$2,'Programa Drench'!$B$5:$AA$5,0),FALSE)*R9),0) -> 80 | R9: =IFERROR(ROUND((O9*$I9),-1),0) -> 400 | S9: =IFERROR(ROUND(IF($D9="SSJ",(VLOOKUP($H9,'Programa Drench'!$B$6:$AA$182,MATCH(S$2,'Programa Drench'!$B$5:$AA$5,0),FALSE)),VLOOKUP($H9,'Programa Drench'!$B$6:$AA$182,MATCH(S$2,'Programa Drench'!$B$5:$AA$5,0),FALSE)),1),0) -> 0 | T9: =IFERROR((VLOOKUP($H9,'Programa Drench'!$B$6:$AA$182,MATCH(T$2,'Programa Drench'!$B$5:$AA$5,0),FALSE)),0) -> 0 | U9: =IFERROR((VLOOKUP($H9,'Programa Drench'!$B$6:$AA$182,MATCH(U$2,'Programa Drench'!$B$5:$AA$5,0),FALSE)*V9),0) -> 0 | V9: =IFERROR(ROUND((S9*$I9),-1),0) -> 0 | W9: =IFERROR(ROUND(IF($D9="SSJ",(VLOOKUP($H9,'Programa Drench'!$B$6:$AA$182,MATCH(W$2,'Programa Drench'!$B$5:$AA$5,0),FALSE)),VLOOKUP($H9,'Programa Drench'!$B$6:$AA$182,MATCH(W$2,'Programa Drench'!$B$5:$AA$5,0),FALSE)),1),0) -> 0 | X9: =IFERROR((VLOOKUP($H9,'Programa Drench'!$B$6:$AA$182,MATCH(X$2,'Programa Drench'!$B$5:$AA$5,0),FALSE)),0) -> 0 | Y9: =IFERROR((VLOOKUP($H9,'Programa Drench'!$B$6:$AA$182,MATCH(Y$2,'Programa Drench'!$B$5:$AA$5,0),FALSE)*Z9),0) -> 0 | Z9: =IFERROR(ROUND((W9*$I9),-1),0) -> 0 | AA9: =IFERROR(ROUND(IF($D9="SSJ",(VLOOKUP($H9,'Programa Drench'!$B$6:$AA$182,MATCH(AA$2,'Programa Drench'!$B$5:$AA$5,0),FALSE)),VLOOKUP($H9,'Programa Drench'!$B$6:$AA$182,MATCH(AA$2,'Programa Drench'!$B$5:$AA$5,0),FALSE)),1),0) -> 0 | AB9: =IFERROR((VLOOKUP($H9,'Programa Drench'!$B$6:$AA$182,MATCH(AB$2,'Programa Drench'!$B$5:$AA$5,0),FALSE)),0) -> 0 | AC9: =IFERROR((VLOOKUP($H9,'Programa Drench'!$B$6:$AA$182,MATCH(AC$2,'Programa Drench'!$B$5:$AA$5,0),FALSE)*$I9),0) -> 0 | AD9: =IFERROR(ROUND((AA9*$I9),-1),0) -> 0 | AE9: =IFERROR(ROUND((VLOOKUP($H9,'Programa Drench'!$B$6:$AA$182,MATCH(AE$2,'Programa Drench'!$B$5:$AA$5,0),FALSE)),-1),0) -> 0 | AF9: =IFERROR((VLOOKUP($H9,'Programa Drench'!$B$6:$AA$182,MATCH(AF$2,'Programa Drench'!$B$5:$AA$5,0),FALSE)),0) -> 0 | AG9: =IFERROR((VLOOKUP($H9,'Programa Drench'!$B$6:$AA$182,MATCH(AG$2,'Programa Drench'!$B$5:$AA$5,0),FALSE)*AH9),0) -> 0 | AH9: =IFERROR(ROUND((VLOOKUP($H9,'Programa Drench'!$B$6:$AA$182,MATCH(AH$2,'Programa Drench'!$B$5:$AA$5,0),FALSE)*$I9),-1),0) -> 0 | AI9: =IFERROR((VLOOKUP($H9,'Programa Drench'!$B$6:$AA$182,MATCH(AI$2,'Programa Drench'!$B$5:$AA$5,0),FALSE)),0) -> 2.2
A10: =IF(($J$1-C10)>=52,($J$1-C10-100+52+1),($J$1-C10+1)) -> 10 | B10: 26A | C10: 2610 | D10: CV | E10: S | F10: CLO | G10: =MID(E10,1,1) -> S | H10: =CONCATENATE(A10," ",G10," ",F10) -> 10 S CLO | I10: =IF(D10="MM1",VLOOKUP($B10,'Inf Bloques'!$A$1:$K$453,11,FALSE)*1,VLOOKUP($B10,'Inf Bloques'!$A$1:$K$453,11,FALSE)) -> 16.15 | J10: =I10/9 -> 1.7944444 | K10: =IFERROR(ROUND(IF($D10="SSJ",(VLOOKUP($H10,'Programa Drench'!$B$6:$AA$182,MATCH(K$2,'Programa Drench'!$B$5:$AA$5,0),FALSE)),VLOOKUP($H10,'Programa Drench'!$B$6:$AA$182,MATCH(K$2,'Programa Drench'!$B$5:$AA$5,0),FALSE)),1),0) -> 50 | L10: =IFERROR((VLOOKUP($H10,'Programa Drench'!$B$6:$AA$182,MATCH(L$2,'Programa Drench'!$B$5:$AA$5,0),FALSE)),0) -> Beauveria | M10: =IFERROR((VLOOKUP($H10,'Programa Drench'!$B$6:$AA$182,MATCH(M$2,'Programa Drench'!$B$5:$AA$5,0),FALSE)*N10),0) -> 4860 | N10: =IFERROR(ROUND((K10*$I10),-1),0) -> 810 | O10: =IFERROR(ROUND(IF($D10="SSJ",(VLOOKUP($H10,'Programa Drench'!$B$6:$AA$182,MATCH(O$2,'Programa Drench'!$B$5:$AA$5,0),FALSE)),VLOOKUP($H10,'Programa Drench'!$B$6:$AA$182,MATCH(O$2,'Programa Drench'!$B$5:$AA$5,0),FALSE)),1),0) -> 50 | P10: =IFERROR((VLOOKUP($H10,'Programa Drench'!$B$6:$AA$182,MATCH(P$2,'Programa Drench'!$B$5:$AA$5,0),FALSE)),0) -> Paecilomyces | Q10: =IFERROR((VLOOKUP($H10,'Programa Drench'!$B$6:$AA$182,MATCH(Q$2,'Programa Drench'!$B$5:$AA$5,0),FALSE)*R10),0) -> 6480 | R10: =IFERROR(ROUND((O10*$I10),-1),0) -> 810 | S10: =IFERROR(ROUND(IF($D10="SSJ",(VLOOKUP($H10,'Programa Drench'!$B$6:$AA$182,MATCH(S$2,'Programa Drench'!$B$5:$AA$5,0),FALSE)),VLOOKUP($H10,'Programa Drench'!$B$6:$AA$182,MATCH(S$2,'Programa Drench'!$B$5:$AA$5,0),FALSE)),1),0) -> 0 | T10: =IFERROR((VLOOKUP($H10,'Programa Drench'!$B$6:$AA$182,MATCH(T$2,'Programa Drench'!$B$5:$AA$5,0),FALSE)),0) -> 0 | U10: =IFERROR((VLOOKUP($H10,'Programa Drench'!$B$6:$AA$182,MATCH(U$2,'Programa Drench'!$B$5:$AA$5,0),FALSE)*V10),0) -> 0 | V10: =IFERROR(ROUND((S10*$I10),-1),0) -> 0 | W10: =IFERROR(ROUND(IF($D10="SSJ",(VLOOKUP($H10,'Programa Drench'!$B$6:$AA$182,MATCH(W$2,'Programa Drench'!$B$5:$AA$5,0),FALSE)),VLOOKUP($H10,'Programa Drench'!$B$6:$AA$182,MATCH(W$2,'Programa Drench'!$B$5:$AA$5,0),FALSE)),1),0) -> 0 | X10: =IFERROR((VLOOKUP($H10,'Programa Drench'!$B$6:$AA$182,MATCH(X$2,'Programa Drench'!$B$5:$AA$5,0),FALSE)),0) -> 0 | Y10: =IFERROR((VLOOKUP($H10,'Programa Drench'!$B$6:$AA$182,MATCH(Y$2,'Programa Drench'!$B$5:$AA$5,0),FALSE)*Z10),0) -> 0 | Z10: =IFERROR(ROUND((W10*$I10),-1),0) -> 0 | AA10: =IFERROR(ROUND(IF($D10="SSJ",(VLOOKUP($H10,'Programa Drench'!$B$6:$AA$182,MATCH(AA$2,'Programa Drench'!$B$5:$AA$5,0),FALSE)),VLOOKUP($H10,'Programa Drench'!$B$6:$AA$182,MATCH(AA$2,'Programa Drench'!$B$5:$AA$5,0),FALSE)),1),0) -> 50 | AB10: =IFERROR((VLOOKUP($H10,'Programa Drench'!$B$6:$AA$182,MATCH(AB$2,'Programa Drench'!$B$5:$AA$5,0),FALSE)),0) -> Trichoderma | AC10: =IFERROR((VLOOKUP($H10,'Programa Drench'!$B$6:$AA$182,MATCH(AC$2,'Programa Drench'!$B$5:$AA$5,0),FALSE)*$I10),0) -> 16.15 | AD10: =IFERROR(ROUND((AA10*$I10),-1),0) -> 810 | AE10: =IFERROR(ROUND((VLOOKUP($H10,'Programa Drench'!$B$6:$AA$182,MATCH(AE$2,'Programa Drench'!$B$5:$AA$5,0),FALSE)),-1),0) -> 0 | AF10: =IFERROR((VLOOKUP($H10,'Programa Drench'!$B$6:$AA$182,MATCH(AF$2,'Programa Drench'!$B$5:$AA$5,0),FALSE)),0) -> 0 | AG10: =IFERROR((VLOOKUP($H10,'Programa Drench'!$B$6:$AA$182,MATCH(AG$2,'Programa Drench'!$B$5:$AA$5,0),FALSE)*AH10),0) -> 0 | AH10: =IFERROR(ROUND((VLOOKUP($H10,'Programa Drench'!$B$6:$AA$182,MATCH(AH$2,'Programa Drench'!$B$5:$AA$5,0),FALSE)*$I10),-1),0) -> 0 | AI10: =IFERROR((VLOOKUP($H10,'Programa Drench'!$B$6:$AA$182,MATCH(AI$2,'Programa Drench'!$B$5:$AA$5,0),FALSE)),0) -> 15
A11: =IF(($J$1-C11)>=52,($J$1-C11-100+52+1),($J$1-C11+1)) -> 9 | B11: 14 | C11: 2611 | D11: CV | E11: P3 | F11: XL | G11: =MID(E11,1,1) -> P | H11: =CONCATENATE(A11," ",G11," ",F11) -> 9 P XL | I11: =IF(D11="MM1",VLOOKUP($B11,'Inf Bloques'!$A$1:$K$453,11,FALSE)*1,VLOOKUP($B11,'Inf Bloques'!$A$1:$K$453,11,FALSE)) -> 39.599167 | J11: =I11/9 -> 4.3999074 | K11: =IFERROR(ROUND(IF($D11="SSJ",(VLOOKUP($H11,'Programa Drench'!$B$6:$AA$182,MATCH(K$2,'Programa Drench'!$B$5:$AA$5,0),FALSE)),VLOOKUP($H11,'Programa Drench'!$B$6:$AA$182,MATCH(K$2,'Programa Drench'!$B$5:$AA$5,0),FALSE)),1),0) -> 50 | L11: =IFERROR((VLOOKUP($H11,'Programa Drench'!$B$6:$AA$182,MATCH(L$2,'Programa Drench'!$B$5:$AA$5,0),FALSE)),0) -> Beauveria | M11: =IFERROR((VLOOKUP($H11,'Programa Drench'!$B$6:$AA$182,MATCH(M$2,'Programa Drench'!$B$5:$AA$5,0),FALSE)*N11),0) -> 11880 | N11: =IFERROR(ROUND((K11*$I11),-1),0) -> 1980 | O11: =IFERROR(ROUND(IF($D11="SSJ",(VLOOKUP($H11,'Programa Drench'!$B$6:$AA$182,MATCH(O$2,'Programa Drench'!$B$5:$AA$5,0),FALSE)),VLOOKUP($H11,'Programa Drench'!$B$6:$AA$182,MATCH(O$2,'Programa Drench'!$B$5:$AA$5,0),FALSE)),1),0) -> 50 | P11: =IFERROR((VLOOKUP($H11,'Programa Drench'!$B$6:$AA$182,MATCH(P$2,'Programa Drench'!$B$5:$AA$5,0),FALSE)),0) -> Paecilomyces | Q11: =IFERROR((VLOOKUP($H11,'Programa Drench'!$B$6:$AA$182,MATCH(Q$2,'Programa Drench'!$B$5:$AA$5,0),FALSE)*R11),0) -> 15840 | R11: =IFERROR(ROUND((O11*$I11),-1),0) -> 1980 | S11: =IFERROR(ROUND(IF($D11="SSJ",(VLOOKUP($H11,'Programa Drench'!$B$6:$AA$182,MATCH(S$2,'Programa Drench'!$B$5:$AA$5,0),FALSE)),VLOOKUP($H11,'Programa Drench'!$B$6:$AA$182,MATCH(S$2,'Programa Drench'!$B$5:$AA$5,0),FALSE)),1),0) -> 0 | T11: =IFERROR((VLOOKUP($H11,'Programa Drench'!$B$6:$AA$182,MATCH(T$2,'Programa Drench'!$B$5:$AA$5,0),FALSE)),0) -> 0 | U11: =IFERROR((VLOOKUP($H11,'Programa Drench'!$B$6:$AA$182,MATCH(U$2,'Programa Drench'!$B$5:$AA$5,0),FALSE)*V11),0) -> 0 | V11: =IFERROR(ROUND((S11*$I11),-1),0) -> 0 | W11: =IFERROR(ROUND(IF($D11="SSJ",(VLOOKUP($H11,'Programa Drench'!$B$6:$AA$182,MATCH(W$2,'Programa Drench'!$B$5:$AA$5,0),FALSE)),VLOOKUP($H11,'Programa Drench'!$B$6:$AA$182,MATCH(W$2,'Programa Drench'!$B$5:$AA$5,0),FALSE)),1),0) -> 0 | X11: =IFERROR((VLOOKUP($H11,'Programa Drench'!$B$6:$AA$182,MATCH(X$2,'Programa Drench'!$B$5:$AA$5,0),FALSE)),0) -> 0 | Y11: =IFERROR((VLOOKUP($H11,'Programa Drench'!$B$6:$AA$182,MATCH(Y$2,'Programa Drench'!$B$5:$AA$5,0),FALSE)*Z11),0) -> 0 | Z11: =IFERROR(ROUND((W11*$I11),-1),0) -> 0 | AA11: =IFERROR(ROUND(IF($D11="SSJ",(VLOOKUP($H11,'Programa Drench'!$B$6:$AA$182,MATCH(AA$2,'Programa Drench'!$B$5:$AA$5,0),FALSE)),VLOOKUP($H11,'Programa Drench'!$B$6:$AA$182,MATCH(AA$2,'Programa Drench'!$B$5:$AA$5,0),FALSE)),1),0) -> 50 | AB11: =IFERROR((VLOOKUP($H11,'Programa Drench'!$B$6:$AA$182,MATCH(AB$2,'Programa Drench'!$B$5:$AA$5,0),FALSE)),0) -> Trichoderma | AC11: =IFERROR((VLOOKUP($H11,'Programa Drench'!$B$6:$AA$182,MATCH(AC$2,'Programa Drench'!$B$5:$AA$5,0),FALSE)*$I11),0) -> 39.599167 | AD11: =IFERROR(ROUND((AA11*$I11),-1),0) -> 1980 | AE11: =IFERROR(ROUND((VLOOKUP($H11,'Programa Drench'!$B$6:$AA$182,MATCH(AE$2,'Programa Drench'!$B$5:$AA$5,0),FALSE)),-1),0) -> 0 | AF11: =IFERROR((VLOOKUP($H11,'Programa Drench'!$B$6:$AA$182,MATCH(AF$2,'Programa Drench'!$B$5:$AA$5,0),FALSE)),0) -> 0 | AG11: =IFERROR((VLOOKUP($H11,'Programa Drench'!$B$6:$AA$182,MATCH(AG$2,'Programa Drench'!$B$5:$AA$5,0),FALSE)*AH11),0) -> 0 | AH11: =IFERROR(ROUND((VLOOKUP($H11,'Programa Drench'!$B$6:$AA$182,MATCH(AH$2,'Programa Drench'!$B$5:$AA$5,0),FALSE)*$I11),-1),0) -> 0 | AI11: =IFERROR((VLOOKUP($H11,'Programa Drench'!$B$6:$AA$182,MATCH(AI$2,'Programa Drench'!$B$5:$AA$5,0),FALSE)),0) -> 15
A12: =IF(($J$1-C12)>=52,($J$1-C12-100+52+1),($J$1-C12+1)) -> 8 | B12: 7 | C12: 2612 | D12: CV | E12: P3 | F12: XL | G12: =MID(E12,1,1) -> P | H12: =CONCATENATE(A12," ",G12," ",F12) -> 8 P XL | I12: =IF(D12="MM1",VLOOKUP($B12,'Inf Bloques'!$A$1:$K$453,11,FALSE)*1,VLOOKUP($B12,'Inf Bloques'!$A$1:$K$453,11,FALSE)) -> 38.4104 | J12: =I12/9 -> 4.2678222 | K12: =IFERROR(ROUND(IF($D12="SSJ",(VLOOKUP($H12,'Programa Drench'!$B$6:$AA$182,MATCH(K$2,'Programa Drench'!$B$5:$AA$5,0),FALSE)),VLOOKUP($H12,'Programa Drench'!$B$6:$AA$182,MATCH(K$2,'Programa Drench'!$B$5:$AA$5,0),FALSE)),1),0) -> 50 | L12: =IFERROR((VLOOKUP($H12,'Programa Drench'!$B$6:$AA$182,MATCH(L$2,'Programa Drench'!$B$5:$AA$5,0),FALSE)),0) -> RAIZA | M12: =IFERROR((VLOOKUP($H12,'Programa Drench'!$B$6:$AA$182,MATCH(M$2,'Programa Drench'!$B$5:$AA$5,0),FALSE)*N12),0) -> 633.6 | N12: =IFERROR(ROUND((K12*$I12),-1),0) -> 1920 | O12: =IFERROR(ROUND(IF($D12="SSJ",(VLOOKUP($H12,'Programa Drench'!$B$6:$AA$182,MATCH(O$2,'Programa Drench'!$B$5:$AA$5,0),FALSE)),VLOOKUP($H12,'Programa Drench'!$B$6:$AA$182,MATCH(O$2,'Programa Drench'!$B$5:$AA$5,0),FALSE)),1),0) -> 50 | P12: =IFERROR((VLOOKUP($H12,'Programa Drench'!$B$6:$AA$182,MATCH(P$2,'Programa Drench'!$B$5:$AA$5,0),FALSE)),0) -> HUMISTAR WG | Q12: =IFERROR((VLOOKUP($H12,'Programa Drench'!$B$6:$AA$182,MATCH(Q$2,'Programa Drench'!$B$5:$AA$5,0),FALSE)*R12),0) -> 384 | R12: =IFERROR(ROUND((O12*$I12),-1),0) -> 1920 | S12: =IFERROR(ROUND(IF($D12="SSJ",(VLOOKUP($H12,'Programa Drench'!$B$6:$AA$182,MATCH(S$2,'Programa Drench'!$B$5:$AA$5,0),FALSE)),VLOOKUP($H12,'Programa Drench'!$B$6:$AA$182,MATCH(S$2,'Programa Drench'!$B$5:$AA$5,0),FALSE)),1),0) -> 50 | T12: =IFERROR((VLOOKUP($H12,'Programa Drench'!$B$6:$AA$182,MATCH(T$2,'Programa Drench'!$B$5:$AA$5,0),FALSE)),0) -> Serenade | U12: =IFERROR((VLOOKUP($H12,'Programa Drench'!$B$6:$AA$182,MATCH(U$2,'Programa Drench'!$B$5:$AA$5,0),FALSE)*V12),0) -> 345.6 | V12: =IFERROR(ROUND((S12*$I12),-1),0) -> 1920 | W12: =IFERROR(ROUND(IF($D12="SSJ",(VLOOKUP($H12,'Programa Drench'!$B$6:$AA$182,MATCH(W$2,'Programa Drench'!$B$5:$AA$5,0),FALSE)),VLOOKUP($H12,'Programa Drench'!$B$6:$AA$182,MATCH(W$2,'Programa Drench'!$B$5:$AA$5,0),FALSE)),1),0) -> 0 | X12: =IFERROR((VLOOKUP($H12,'Programa Drench'!$B$6:$AA$182,MATCH(X$2,'Programa Drench'!$B$5:$AA$5,0),FALSE)),0) -> 0 | Y12: =IFERROR((VLOOKUP($H12,'Programa Drench'!$B$6:$AA$182,MATCH(Y$2,'Programa Drench'!$B$5:$AA$5,0),FALSE)*Z12),0) -> 0 | Z12: =IFERROR(ROUND((W12*$I12),-1),0) -> 0 | AA12: =IFERROR(ROUND(IF($D12="SSJ",(VLOOKUP($H12,'Programa Drench'!$B$6:$AA$182,MATCH(AA$2,'Programa Drench'!$B$5:$AA$5,0),FALSE)),VLOOKUP($H12,'Programa Drench'!$B$6:$AA$182,MATCH(AA$2,'Programa Drench'!$B$5:$AA$5,0),FALSE)),1),0) -> 0 | AB12: =IFERROR((VLOOKUP($H12,'Programa Drench'!$B$6:$AA$182,MATCH(AB$2,'Programa Drench'!$B$5:$AA$5,0),FALSE)),0) -> 0 | AC12: =IFERROR((VLOOKUP($H12,'Programa Drench'!$B$6:$AA$182,MATCH(AC$2,'Programa Drench'!$B$5:$AA$5,0),FALSE)*$I12),0) -> 0 | AD12: =IFERROR(ROUND((AA12*$I12),-1),0) -> 0 | AE12: =IFERROR(ROUND((VLOOKUP($H12,'Programa Drench'!$B$6:$AA$182,MATCH(AE$2,'Programa Drench'!$B$5:$AA$5,0),FALSE)),-1),0) -> 0 | AF12: =IFERROR((VLOOKUP($H12,'Programa Drench'!$B$6:$AA$182,MATCH(AF$2,'Programa Drench'!$B$5:$AA$5,0),FALSE)),0) -> 0 | AG12: =IFERROR((VLOOKUP($H12,'Programa Drench'!$B$6:$AA$182,MATCH(AG$2,'Programa Drench'!$B$5:$AA$5,0),FALSE)*AH12),0) -> 0 | AH12: =IFERROR(ROUND((VLOOKUP($H12,'Programa Drench'!$B$6:$AA$182,MATCH(AH$2,'Programa Drench'!$B$5:$AA$5,0),FALSE)*$I12),-1),0) -> 0 | AI12: =IFERROR((VLOOKUP($H12,'Programa Drench'!$B$6:$AA$182,MATCH(AI$2,'Programa Drench'!$B$5:$AA$5,0),FALSE)),0) -> 0.71
